<?xml version="1.0" ?>
<!-- =================================================================================== -->
<!-- |    This document was autogenerated by xacro from four_wheel_bot.xacro           | -->
<!-- |    EDITING THIS FILE BY HAND IS NOT RECOMMENDED                                 | -->
<!-- =================================================================================== -->
<robot name="four_wheel_bot">
  <!-- Define materials -->
  <material name="black">
    <color rgba="0 0 0 1"/>
  </material>
  <material name="blue">
    <color rgba="0 0 1 1"/>
  </material>
  <!-- Base link -->
  <link name="base_link">
    <visual>
      <geometry>
        <box size="1 1 0.5"/>
      </geometry>
      <material name="blue"/>
    </visual>
    <collision>
      <origin rpy="1.5708 0 0"/>
      <geometry>
        <box size="1 1 0.5"/>
      </geometry>
    </collision>
    <inertial>
      <mass value="1.0"/>
      <inertia ixx="0.1" ixy="0.0" ixz="0.0" iyy="0.1" iyz="0.0" izz="0.1"/>
    </inertial>
  </link>
  <!-- Apply Gazebo material to base_link -->
  <gazebo reference="base_link">
    <material>Gazebo/Blue</material>
  </gazebo>
  <link name="front_left_wheel">
    <visual>
      <origin rpy="1.5708 0 0"/>
      <geometry>
        <cylinder length="0.25" radius="0.25"/>
      </geometry>
      <material name="black"/>
    </visual>
    <collision>
      <origin rpy="1.5708 0 0"/>
      <geometry>
        <cylinder length="0.25" radius="0.25"/>
      </geometry>
    </collision>
    <inertial>
      <mass value="0.2"/>
      <inertia ixx="0.01" ixy="0.0" ixz="0.0" iyy="0.01" iyz="0.0" izz="0.01"/>
    </inertial>
  </link>
  <gazebo reference="front_left_wheel">
    <material>Gazebo/Black</material>
  </gazebo>
  <joint name="front_left_joint" type="continuous">
    <parent link="base_link"/>
    <child link="front_left_wheel"/>
    <origin rpy="0 0 0" xyz="0.5 0.5 -0.25"/>
    <axis xyz="0 1 0"/>
  </joint>
  <link name="front_right_wheel">
    <visual>
      <origin rpy="1.5708 0 0"/>
      <geometry>
        <cylinder length="0.25" radius="0.25"/>
      </geometry>
      <material name="black"/>
    </visual>
    <collision>
      <origin rpy="1.5708 0 0"/>
      <geometry>
        <cylinder length="0.25" radius="0.25"/>
      </geometry>
    </collision>
    <inertial>
      <mass value="0.2"/>
      <inertia ixx="0.01" ixy="0.0" ixz="0.0" iyy="0.01" iyz="0.0" izz="0.01"/>
    </inertial>
  </link>
  <gazebo reference="front_right_wheel">
    <material>Gazebo/Black</material>
  </gazebo>
  <joint name="front_right_joint" type="continuous">
    <parent link="base_link"/>
    <child link="front_right_wheel"/>
    <origin rpy="0 0 0" xyz="0.5 -0.5 -0.25"/>
    <axis xyz="0 1 0"/>
  </joint>
  <link name="rear_left_wheel">
    <visual>
      <origin rpy="1.5708 0 0"/>
      <geometry>
        <cylinder length="0.25" radius="0.25"/>
      </geometry>
      <material name="black"/>
    </visual>
    <collision>
      <origin rpy="1.5708 0 0"/>
      <geometry>
        <cylinder length="0.25" radius="0.25"/>
      </geometry>
    </collision>
    <inertial>
      <mass value="0.2"/>
      <inertia ixx="0.01" ixy="0.0" ixz="0.0" iyy="0.01" iyz="0.0" izz="0.01"/>
    </inertial>
  </link>
  <gazebo reference="rear_left_wheel">
    <material>Gazebo/Black</material>
  </gazebo>
  <joint name="rear_left_joint" type="continuous">
    <parent link="base_link"/>
    <child link="rear_left_wheel"/>
    <origin rpy="0 0 0" xyz="-0.5 0.5 -0.25"/>
    <axis xyz="0 1 0"/>
  </joint>
  <link name="rear_right_wheel">
    <visual>
      <origin rpy="1.5708 0 0"/>
      <geometry>
        <cylinder length="0.25" radius="0.25"/>
      </geometry>
      <material name="black"/>
    </visual>
    <collision>
      <origin rpy="1.5708 0 0"/>
      <geometry>
        <cylinder length="0.25" radius="0.25"/>
      </geometry>
    </collision>
    <inertial>
      <mass value="0.2"/>
      <inertia ixx="0.01" ixy="0.0" ixz="0.0" iyy="0.01" iyz="0.0" izz="0.01"/>
    </inertial>
  </link>
  <gazebo reference="rear_right_wheel">
    <material>Gazebo/Black</material>
  </gazebo>
  <joint name="rear_right_joint" type="continuous">
    <parent link="base_link"/>
    <child link="rear_right_wheel"/>
    <origin rpy="0 0 0" xyz="-0.5 -0.5 -0.25"/>
    <axis xyz="0 1 0"/>
  </joint>
  <!-- Gazebo Differential Drive Plugin -->
  <gazebo>
    <plugin filename="libgazebo_ros_diff_drive.so" name="diff_drive_controller">
      <ros>
        <namespace>/</namespace>
        <remapping>cmd_vel:=cmd_vel</remapping>
      </ros>
      <update_rate>50.0</update_rate>
      <!-- Correct format: multiple left_joint/right_joint tags -->
      <!-- All left wheel joints -->
      <left_joint>front_left_joint</left_joint>
      <left_joint>rear_left_joint</left_joint>
      <!-- All right wheel joints -->
      <right_joint>front_right_joint</right_joint>
      <right_joint>rear_right_joint</right_joint>
      <wheel_separation>1.0</wheel_separation>
      <!-- distance between left and right wheels -->
      <wheel_diameter>0.5</wheel_diameter>
      <wheel_radius>0.25</wheel_radius>
      <wheel_acceleration>1.0</wheel_acceleration>
      <wheel_torque>5.0</wheel_torque>
      <command_topic>cmd_vel</command_topic>
      <odometry_topic>odom</odometry_topic>
      <odometry_frame>odom</odometry_frame>
      <robot_base_frame>base_link</robot_base_frame>
      <publish_odom>true</publish_odom>
      <publish_odom_tf>true</publish_odom_tf>
    </plugin>
  </gazebo>
</robot>
