<?xml version="1.0"?>
<robot xmlns:xacro="http://www.ros.org/wiki/xacro" name="four_wheel_bot">


  <material name="black">
    <color rgba="0 0 0 1"/>
  </material>
  <material name="blue">
    <color rgba="0 0 1 1"/>
  </material>

  <xacro:property name="wheel_radius" value="0.25"/>
  <xacro:property name="wheel_length" value="0.25"/>
  <xacro:property name="wheel_color" value="black"/>

  <link name="base_link">
    <visual>
      <geometry>
        <box size="1 1 0.5"/>
      </geometry>
      <material name="blue"/>
    </visual>
    <collision>
      <geometry>
        <box size="1 1 0.5"/>
      </geometry>
    </collision>
    <inertial>
      <mass value="1"/>
      <inertia ixx="0.1" ixy="0.0" ixz="0.0" iyy="0.1" iyz="0.0" izz="0.1"/>
    </inertial>
  </link>

  <gazebo reference="base_link">
    <material>Gazebo/Green</material>
  </gazebo>

  <link name="lidar_stand_link">
    <visual>
      <origin xyz="0 0 0.15"/>
      <geometry>
        <cylinder radius="0.02" length="0.3"/>
      </geometry>
      <material name="black"/>
    </visual>
    <collision>
      <origin xyz="0 0 0.15"/>
      <geometry>
        <cylinder radius="0.02" length="0.3"/>
      </geometry>
    </collision>
    <inertial>
      <mass value="0.05"/>
      <inertia ixx="0.0001" ixy="0" ixz="0" iyy="0.0001" iyz="0" izz="0.0001"/>
    </inertial>
  </link>

  <joint name="lidar_stand_joint" type="fixed">
    <parent link="base_link"/>
    <child link="lidar_stand_link"/>
    <origin xyz="0 0 0.25"/>
  </joint>

  <xacro:macro name="wheel_with_joint" params="wheel_name joint_name x y z">
    <link name="${wheel_name}">
      <visual>
        <origin rpy="1.5708 0 0"/>
        <geometry>
          <cylinder length="${wheel_length}" radius="${wheel_radius}"/>
        </geometry>
        <material name="${wheel_color}"/>
      </visual>
      <collision>
        <origin rpy="1.5708 0 0"/>
        <geometry>
          <cylinder length="${wheel_length}" radius="${wheel_radius}"/>
        </geometry>
      </collision>
      <inertial>
        <mass value="0.2"/>
        <inertia ixx="0.01" ixy="0" ixz="0" iyy="0.01" iyz="0" izz="0.01"/>
      </inertial>
    </link>

    <gazebo reference="${wheel_name}">
      <material>Gazebo/Black</material>
    </gazebo>

    <joint name="${joint_name}" type="continuous">
      <parent link="base_link"/>
      <child link="${wheel_name}"/>
      <origin xyz="${x} ${y} ${z}"/>
      <axis xyz="0 1 0"/>
      <limit effort="1.0" velocity="1.0"/>
    </joint>
  </xacro:macro>

  <xacro:wheel_with_joint wheel_name="front_left_wheel"  joint_name="front_left_joint"  x="0.5"  y="0.5"  z="-0.25"/>
  <xacro:wheel_with_joint wheel_name="front_right_wheel" joint_name="front_right_joint" x="0.5"  y="-0.5" z="-0.25"/>
  <xacro:wheel_with_joint wheel_name="rear_left_wheel"   joint_name="rear_left_joint"   x="-0.5" y="0.5"  z="-0.25"/>
  <xacro:wheel_with_joint wheel_name="rear_right_wheel"  joint_name="rear_right_joint"  x="-0.5" y="-0.5" z="-0.25"/>

  <transmission name="rear_left_trans">
    <type>transmission_interface/SimpleTransmission</type>
    <joint name="rear_left_joint">
      <hardwareInterface>hardware_interface/VelocityJointInterface</hardwareInterface>
    </joint>
    <actuator name="rear_left_motor">
      <mechanicalReduction>1</mechanicalReduction>
    </actuator>
  </transmission>

  <transmission name="rear_right_trans">
    <type>transmission_interface/SimpleTransmission</type>
    <joint name="rear_right_joint">
      <hardwareInterface>hardware_interface/VelocityJointInterface</hardwareInterface>
    </joint>
    <actuator name="rear_right_motor">
      <mechanicalReduction>1</mechanicalReduction>
    </actuator>
  </transmission>

  <gazebo>
    <plugin name="diff_drive_controller" filename="libgazebo_ros_diff_drive.so">
      <ros>
        <namespace>/</namespace>
        <remapping>cmd_vel:=cmd_vel</remapping>
      </ros>
      <update_rate>50.0</update_rate>
      <left_joint>rear_left_joint</left_joint>
      <right_joint>rear_right_joint</right_joint>
      <wheel_separation>1.0</wheel_separation>
      <wheel_radius>${wheel_radius}</wheel_radius>
      <wheel_diameter>0.5</wheel_diameter>
      <wheel_acceleration>1.0</wheel_acceleration>
      <wheel_torque>10.0</wheel_torque>
      <publish_wheel_tf>true</publish_wheel_tf>
      <publish_wheel_joint_state>true</publish_wheel_joint_state>
      <legacy_mode>false</legacy_mode>
    </plugin>
  </gazebo>

  <link name="lidar_link">
    <visual>
      <origin xyz="0 0 0.15"/>
      <geometry>
        <cylinder radius="0.05" length="0.1"/>
      </geometry>
      <material name="black"/>
    </visual>
    <collision>
      <origin xyz="0 0 0.15"/>
      <geometry>
        <cylinder radius="0.05" length="0.1"/>
      </geometry>
    </collision>
    <inertial>
      <mass value="0.1"/>
      <inertia ixx="0.0001" ixy="0" ixz="0" iyy="0.0001" iyz="0" izz="0.0001"/>
    </inertial>
  </link>

  <joint name="lidar_joint" type="fixed">
    <parent link="lidar_stand_link"/>
    <child link="lidar_link"/>
    <origin xyz="0 0 0.15"/>
  </joint>

  <gazebo reference="lidar_link">
    <sensor name="lidar_sensor" type="ray">
      <always_on>true</always_on>
      <update_rate>10.0</update_rate>
      <visualize>true</visualize>
      <ray>
        <scan>
          <horizontal>
            <samples>720</samples>
            <resolution>1</resolution>
            <min_angle>-1.39626</min_angle>
            <max_angle>1.39626</max_angle>
          </horizontal>
        </scan>
        <range>
          <min>0.12</min>
          <max>10.0</max>
          <resolution>0.01</resolution>
        </range>
        <noise>
          <type>gaussian</type>
          <mean>0.0</mean>
          <stddev>0.01</stddev>
        </noise>
      </ray>
      <plugin name="gazebo_ros_ray_sensor" filename="libgazebo_ros_ray_sensor.so">
        <ros>
          <remapping>~/out:=scan</remapping>
        </ros>
        <frame_name>lidar_link</frame_name>
        <output_type>sensor_msgs/LaserScan</output_type>
      </plugin>
    </sensor>
  </gazebo>


<link name="camera_stand_link">
  <visual>
    <origin xyz="0 0 0.2"/>
    <geometry>
      <cylinder radius="0.02" length="0.4"/>
    </geometry>
    <material name="black"/>
  </visual>
  <collision>
    <origin xyz="0 0 0.2"/>
    <geometry>
      <cylinder radius="0.02" length="0.4"/>
    </geometry>
  </collision>
  <inertial>
    <mass value="0.05"/>
    <inertia ixx="0.0001" ixy="0" ixz="0" iyy="0.0001" iyz="0" izz="0.0001"/>
  </inertial>
</link>

<joint name="camera_stand_joint" type="fixed">
  <parent link="base_link"/>
  <child link="camera_stand_link"/>
  <origin xyz="0 0.3 0.25"/> 
</joint>


<link name="camera_link">
  <visual>
    <origin xyz="0 0 0"/>
    <geometry>
      <box size="0.06 0.06 0.06"/>
    </geometry>
    <material name="black"/>
  </visual>
  <collision>
    <origin xyz="0 0 0"/>
    <geometry>
      <box size="0.06 0.06 0.06"/>
    </geometry>
  </collision>
  <inertial>
    <mass value="0.1"/>
    <inertia ixx="0.001" ixy="0" ixz="0" iyy="0.001" iyz="0" izz="0.001"/>
  </inertial>
</link>

<joint name="camera_joint" type="fixed">
  <parent link="camera_stand_link"/>
  <child link="camera_link"/>
  <origin xyz="0 0 0.4" rpy="0 0 0"/>
</joint>

<gazebo reference="camera_link">
  <sensor name="camera_sensor" type="camera">
    <always_on>true</always_on>
    <update_rate>30.0</update_rate>
    <visualize>true</visualize>
    <camera>
      <horizontal_fov>1.3962634</horizontal_fov>
      <image>
        <width>640</width>
        <height>480</height>
        <format>R8G8B8</format>
      </image>
      <clip>
        <near>0.1</near>
        <far>100</far>
      </clip>
    </camera>
    <plugin name="gazebo_ros_camera" filename="libgazebo_ros_camera.so">
      <ros>
        <remapping>~/image_raw:=camera/image_raw</remapping>
      </ros>
      <camera_name>camera</camera_name>
      <frame_name>camera_link</frame_name>
    </plugin>
  </sensor>
</gazebo>


</robot>
